from fastapi import FastAPI, HTTPException
from pydantic import BaseModel

app = FastAPI()

# Создание класса User, наследованного от BaseModel
class User(BaseModel):
    id: int
    username: str
    age: int

# Инициализация пустого списка пользователей
users = []

# GET запрос для получения всех пользователей
@app.get("/users")
async def get_users():
    return users

# POST запрос для добавления нового пользователя
@app.post("/user/{username}/{age}")
async def create_user(username: str, age: int):
    # Определение ID нового пользователя
    new_user_id = users[-1].id + 1 if users else 1
    new_user = User(id=new_user_id, username=username, age=age)
    users.append(new_user)
    return new_user

# PUT запрос для обновления информации о пользователе
@app.put("/user/{user_id}/{username}/{age}")
async def update_user(user_id: int, username: str, age: int):
    for user in users:
        if user.id == user_id:
            user.username = username
            user.age = age
            return user
    raise HTTPException(status_code=404, detail="User was not found")

# DELETE запрос для удаления пользователя
@app.delete("/user/{user_id}")
async def delete_user(user_id: int):
    for user in users:
        if user.id == user_id:
            users.remove(user)
            return user
    raise HTTPException(status_code=404, detail="User was not found")
